WARNING:root:something raised an exception:
Traceback (most recent call last):
  File "/home/namor/Desktop/Vulnerability-Checker/db_handler.py", line 231, in exec_insert
    cur.execute(query, *params)
pyodbc.ProgrammingError: ('42000', '[42000] [Microsoft][ODBC Driver 17 for SQL Server][SQL Server]Conversion failed when converting from a character string to uniqueidentifier. (8169) (SQLExecDirectW)')
WARNING:root:something raised an exception:
Traceback (most recent call last):
  File "/home/namor/Desktop/Vulnerability-Checker/db_handler.py", line 231, in exec_insert
    cur.execute(query, *params)
pyodbc.ProgrammingError: ('42000', '[42000] [Microsoft][ODBC Driver 17 for SQL Server][SQL Server]Conversion failed when converting from a character string to uniqueidentifier. (8169) (SQLExecDirectW)')
WARNING:root:something raised an exception:
Traceback (most recent call last):
  File "/home/namor/Desktop/Vulnerability-Checker/db_handler.py", line 231, in exec_insert
    cur.execute(query, *params)
pyodbc.ProgrammingError: ('42000', '[42000] [Microsoft][ODBC Driver 17 for SQL Server][SQL Server]Conversion failed when converting from a character string to uniqueidentifier. (8169) (SQLExecDirectW)')
WARNING:root:something raised an exception:
Traceback (most recent call last):
  File "/home/namor/Desktop/Vulnerability-Checker/db_handler.py", line 231, in exec_insert
    cur.execute(query, *params)
pyodbc.ProgrammingError: ('42000', '[42000] [Microsoft][ODBC Driver 17 for SQL Server][SQL Server]Conversion failed when converting from a character string to uniqueidentifier. (8169) (SQLExecDirectW)')
WARNING:root:something raised an exception:
Traceback (most recent call last):
  File "/home/namor/Desktop/Vulnerability-Checker/db_handler.py", line 231, in exec_insert
    cur.execute(query, *params)
pyodbc.ProgrammingError: ('42000', '[42000] [Microsoft][ODBC Driver 17 for SQL Server][SQL Server]Conversion failed when converting from a character string to uniqueidentifier. (8169) (SQLExecDirectW)')
WARNING:root:something raised an exception:
Traceback (most recent call last):
  File "/home/namor/Desktop/Vulnerability-Checker/db_handler.py", line 231, in exec_insert
    cur.execute(query, *params)
pyodbc.ProgrammingError: ('42000', '[42000] [Microsoft][ODBC Driver 17 for SQL Server][SQL Server]Conversion failed when converting from a character string to uniqueidentifier. (8169) (SQLExecDirectW)')
WARNING:root:something raised an exception:
Traceback (most recent call last):
  File "/home/namor/Desktop/Vulnerability-Checker/db_handler.py", line 231, in exec_insert
    cur.execute(query, *params)
pyodbc.ProgrammingError: ('42000', '[42000] [Microsoft][ODBC Driver 17 for SQL Server][SQL Server]Conversion failed when converting from a character string to uniqueidentifier. (8169) (SQLExecDirectW)')
WARNING:root:something raised an exception:
Traceback (most recent call last):
  File "/home/namor/Desktop/Vulnerability-Checker/db_handler.py", line 231, in exec_insert
    cur.execute(query, *params)
pyodbc.ProgrammingError: ('42000', '[42000] [Microsoft][ODBC Driver 17 for SQL Server][SQL Server]Conversion failed when converting from a character string to uniqueidentifier. (8169) (SQLExecDirectW)')
WARNING:root:something raised an exception:
Traceback (most recent call last):
  File "/home/namor/Desktop/Vulnerability-Checker/db_handler.py", line 231, in exec_insert
    cur.execute(query, *params)
pyodbc.ProgrammingError: ('42000', '[42000] [Microsoft][ODBC Driver 17 for SQL Server][SQL Server]Conversion failed when converting from a character string to uniqueidentifier. (8169) (SQLExecDirectW)')
WARNING:root:something raised an exception:
Traceback (most recent call last):
  File "/usr/lib64/python3.6/encodings/utf_16_le.py", line 15, in decode
    def decode(input, errors='strict'):
KeyboardInterrupt

The above exception was the direct cause of the following exception:

KeyboardInterrupt: decoding with 'utf-16le' codec failed (KeyboardInterrupt: )

The above exception was the direct cause of the following exception:

Traceback (most recent call last):
  File "/home/namor/Desktop/Vulnerability-Checker/db_handler.py", line 231, in exec_insert
    cur.execute(query, *params)
SystemError: <class 'pyodbc.Error'> returned a result with an error set

During handling of the above exception, another exception occurred:

Traceback (most recent call last):
  File "/home/namor/Desktop/Vulnerability-Checker/db_handler.py", line 234, in exec_insert
    cur.close()
pyodbc.OperationalError: ('08S01', '[08S01] [Microsoft][ODBC Driver 17 for SQL Server]Communication link failure (-2147467259) (SQLEndTran(SQL_ROLLBACK))')
WARNING:root:something raised an exception:
Traceback (most recent call last):
  File "/home/namor/Desktop/Vulnerability-Checker/db_handler.py", line 231, in exec_insert
    cur.execute(query, *params)
pyodbc.OperationalError: ('08S01', '[08S01] [Microsoft][ODBC Driver 17 for SQL Server]Communication link failure (0) (SQLExecDirectW)')

During handling of the above exception, another exception occurred:

Traceback (most recent call last):
  File "/home/namor/Desktop/Vulnerability-Checker/db_handler.py", line 234, in exec_insert
    cur.close()
pyodbc.OperationalError: ('08S01', '[08S01] [Microsoft][ODBC Driver 17 for SQL Server]Communication link failure (0) (SQLEndTran(SQL_ROLLBACK))')
WARNING:root:something raised an exception:
Traceback (most recent call last):
  File "/home/namor/Desktop/Vulnerability-Checker/db_handler.py", line 231, in exec_insert
    cur.execute(query, *params)
pyodbc.OperationalError: ('08S01', '[08S01] [Microsoft][ODBC Driver 17 for SQL Server]Communication link failure (0) (SQLExecDirectW)')

During handling of the above exception, another exception occurred:

Traceback (most recent call last):
  File "/home/namor/Desktop/Vulnerability-Checker/db_handler.py", line 234, in exec_insert
    cur.close()
pyodbc.OperationalError: ('08S01', '[08S01] [Microsoft][ODBC Driver 17 for SQL Server]Communication link failure (0) (SQLEndTran(SQL_ROLLBACK))')
WARNING:root:something raised an exception:
Traceback (most recent call last):
  File "/home/namor/Desktop/Vulnerability-Checker/db_handler.py", line 231, in exec_insert
    cur.execute(query, *params)
pyodbc.OperationalError: ('08S01', '[08S01] [Microsoft][ODBC Driver 17 for SQL Server]Communication link failure (0) (SQLExecDirectW)')

During handling of the above exception, another exception occurred:

Traceback (most recent call last):
  File "/home/namor/Desktop/Vulnerability-Checker/db_handler.py", line 234, in exec_insert
    cur.close()
pyodbc.OperationalError: ('08S01', '[08S01] [Microsoft][ODBC Driver 17 for SQL Server]Communication link failure (0) (SQLEndTran(SQL_ROLLBACK))')
WARNING:root:something raised an exception:
Traceback (most recent call last):
  File "/home/namor/Desktop/Vulnerability-Checker/db_handler.py", line 231, in exec_insert
    cur.execute(query, *params)
pyodbc.OperationalError: ('08S01', '[08S01] [Microsoft][ODBC Driver 17 for SQL Server]Communication link failure (0) (SQLExecDirectW)')

During handling of the above exception, another exception occurred:

Traceback (most recent call last):
  File "/home/namor/Desktop/Vulnerability-Checker/db_handler.py", line 234, in exec_insert
    cur.close()
pyodbc.OperationalError: ('08S01', '[08S01] [Microsoft][ODBC Driver 17 for SQL Server]Communication link failure (0) (SQLEndTran(SQL_ROLLBACK))')
WARNING:root:something raised an exception:
Traceback (most recent call last):
  File "/home/namor/Desktop/Vulnerability-Checker/db_handler.py", line 231, in exec_insert
    cur.execute(query, *params)
pyodbc.OperationalError: ('08S01', '[08S01] [Microsoft][ODBC Driver 17 for SQL Server]Communication link failure (0) (SQLExecDirectW)')

During handling of the above exception, another exception occurred:

Traceback (most recent call last):
  File "/home/namor/Desktop/Vulnerability-Checker/db_handler.py", line 234, in exec_insert
    cur.close()
pyodbc.OperationalError: ('08S01', '[08S01] [Microsoft][ODBC Driver 17 for SQL Server]Communication link failure (0) (SQLEndTran(SQL_ROLLBACK))')
WARNING:root:something raised an exception:
Traceback (most recent call last):
  File "/home/namor/Desktop/Vulnerability-Checker/db_handler.py", line 231, in exec_insert
    cur.execute(query, *params)
pyodbc.OperationalError: ('08S01', '[08S01] [Microsoft][ODBC Driver 17 for SQL Server]Communication link failure (0) (SQLExecDirectW)')

During handling of the above exception, another exception occurred:

Traceback (most recent call last):
  File "/home/namor/Desktop/Vulnerability-Checker/db_handler.py", line 234, in exec_insert
    cur.close()
pyodbc.OperationalError: ('08S01', '[08S01] [Microsoft][ODBC Driver 17 for SQL Server]Communication link failure (0) (SQLEndTran(SQL_ROLLBACK))')
WARNING:root:something raised an exception:
Traceback (most recent call last):
  File "/home/namor/Desktop/Vulnerability-Checker/db_handler.py", line 231, in exec_insert
    cur.execute(query, *params)
pyodbc.OperationalError: ('08S01', '[08S01] [Microsoft][ODBC Driver 17 for SQL Server]Communication link failure (0) (SQLExecDirectW)')

During handling of the above exception, another exception occurred:

Traceback (most recent call last):
  File "/home/namor/Desktop/Vulnerability-Checker/db_handler.py", line 234, in exec_insert
    cur.close()
pyodbc.OperationalError: ('08S01', '[08S01] [Microsoft][ODBC Driver 17 for SQL Server]Communication link failure (0) (SQLEndTran(SQL_ROLLBACK))')
WARNING:root:something raised an exception:
Traceback (most recent call last):
  File "/home/namor/Desktop/Vulnerability-Checker/db_handler.py", line 231, in exec_insert
    cur.execute(query, *params)
pyodbc.OperationalError: ('08S01', '[08S01] [Microsoft][ODBC Driver 17 for SQL Server]Communication link failure (0) (SQLExecDirectW)')

During handling of the above exception, another exception occurred:

Traceback (most recent call last):
  File "/home/namor/Desktop/Vulnerability-Checker/db_handler.py", line 234, in exec_insert
    cur.close()
pyodbc.OperationalError: ('08S01', '[08S01] [Microsoft][ODBC Driver 17 for SQL Server]Communication link failure (0) (SQLEndTran(SQL_ROLLBACK))')
WARNING:root:something raised an exception:
Traceback (most recent call last):
  File "/home/namor/Desktop/Vulnerability-Checker/db_handler.py", line 231, in exec_insert
    cur.execute(query, *params)
pyodbc.OperationalError: ('08S01', '[08S01] [Microsoft][ODBC Driver 17 for SQL Server]Communication link failure (0) (SQLExecDirectW)')

During handling of the above exception, another exception occurred:

Traceback (most recent call last):
  File "/home/namor/Desktop/Vulnerability-Checker/db_handler.py", line 234, in exec_insert
    cur.close()
pyodbc.OperationalError: ('08S01', '[08S01] [Microsoft][ODBC Driver 17 for SQL Server]Communication link failure (0) (SQLEndTran(SQL_ROLLBACK))')
WARNING:root:something raised an exception:
Traceback (most recent call last):
  File "/home/namor/Desktop/Vulnerability-Checker/db_handler.py", line 231, in exec_insert
    cur.execute(query, *params)
pyodbc.OperationalError: ('08S01', '[08S01] [Microsoft][ODBC Driver 17 for SQL Server]Communication link failure (0) (SQLExecDirectW)')

During handling of the above exception, another exception occurred:

Traceback (most recent call last):
  File "/home/namor/Desktop/Vulnerability-Checker/db_handler.py", line 234, in exec_insert
    cur.close()
pyodbc.OperationalError: ('08S01', '[08S01] [Microsoft][ODBC Driver 17 for SQL Server]Communication link failure (0) (SQLEndTran(SQL_ROLLBACK))')
WARNING:root:something raised an exception:
Traceback (most recent call last):
  File "/home/namor/Desktop/Vulnerability-Checker/db_handler.py", line 231, in exec_insert
    cur.execute(query, *params)
pyodbc.OperationalError: ('08S01', '[08S01] [Microsoft][ODBC Driver 17 for SQL Server]Communication link failure (0) (SQLExecDirectW)')

During handling of the above exception, another exception occurred:

Traceback (most recent call last):
  File "/home/namor/Desktop/Vulnerability-Checker/db_handler.py", line 234, in exec_insert
    cur.close()
pyodbc.OperationalError: ('08S01', '[08S01] [Microsoft][ODBC Driver 17 for SQL Server]Communication link failure (0) (SQLEndTran(SQL_ROLLBACK))')
WARNING:root:something raised an exception:
Traceback (most recent call last):
  File "/home/namor/Desktop/Vulnerability-Checker/db_handler.py", line 231, in exec_insert
    cur.execute(query, *params)
pyodbc.OperationalError: ('08S01', '[08S01] [Microsoft][ODBC Driver 17 for SQL Server]Communication link failure (0) (SQLExecDirectW)')

During handling of the above exception, another exception occurred:

Traceback (most recent call last):
  File "/home/namor/Desktop/Vulnerability-Checker/db_handler.py", line 234, in exec_insert
    cur.close()
pyodbc.OperationalError: ('08S01', '[08S01] [Microsoft][ODBC Driver 17 for SQL Server]Communication link failure (0) (SQLEndTran(SQL_ROLLBACK))')
WARNING:root:something raised an exception:
Traceback (most recent call last):
  File "/home/namor/Desktop/Vulnerability-Checker/db_handler.py", line 231, in exec_insert
    cur.execute(query, *params)
pyodbc.OperationalError: ('08S01', '[08S01] [Microsoft][ODBC Driver 17 for SQL Server]Communication link failure (0) (SQLExecDirectW)')

During handling of the above exception, another exception occurred:

Traceback (most recent call last):
  File "/home/namor/Desktop/Vulnerability-Checker/db_handler.py", line 234, in exec_insert
    cur.close()
pyodbc.OperationalError: ('08S01', '[08S01] [Microsoft][ODBC Driver 17 for SQL Server]Communication link failure (0) (SQLEndTran(SQL_ROLLBACK))')
WARNING:root:something raised an exception:
Traceback (most recent call last):
  File "/home/namor/Desktop/Vulnerability-Checker/db_handler.py", line 231, in exec_insert
    cur.execute(query, *params)
pyodbc.OperationalError: ('08S01', '[08S01] [Microsoft][ODBC Driver 17 for SQL Server]Communication link failure (0) (SQLExecDirectW)')

During handling of the above exception, another exception occurred:

Traceback (most recent call last):
  File "/home/namor/Desktop/Vulnerability-Checker/db_handler.py", line 234, in exec_insert
    cur.close()
pyodbc.OperationalError: ('08S01', '[08S01] [Microsoft][ODBC Driver 17 for SQL Server]Communication link failure (0) (SQLEndTran(SQL_ROLLBACK))')
WARNING:root:something raised an exception:
Traceback (most recent call last):
  File "/home/namor/Desktop/Vulnerability-Checker/db_handler.py", line 231, in exec_insert
    cur.execute(query, *params)
pyodbc.OperationalError: ('08S01', '[08S01] [Microsoft][ODBC Driver 17 for SQL Server]Communication link failure (0) (SQLExecDirectW)')

During handling of the above exception, another exception occurred:

Traceback (most recent call last):
  File "/home/namor/Desktop/Vulnerability-Checker/db_handler.py", line 234, in exec_insert
    cur.close()
pyodbc.OperationalError: ('08S01', '[08S01] [Microsoft][ODBC Driver 17 for SQL Server]Communication link failure (0) (SQLEndTran(SQL_ROLLBACK))')
WARNING:root:something raised an exception:
Traceback (most recent call last):
  File "/home/namor/Desktop/Vulnerability-Checker/db_handler.py", line 231, in exec_insert
    cur.execute(query, *params)
pyodbc.OperationalError: ('08S01', '[08S01] [Microsoft][ODBC Driver 17 for SQL Server]Communication link failure (0) (SQLExecDirectW)')

During handling of the above exception, another exception occurred:

Traceback (most recent call last):
  File "/home/namor/Desktop/Vulnerability-Checker/db_handler.py", line 234, in exec_insert
    cur.close()
pyodbc.OperationalError: ('08S01', '[08S01] [Microsoft][ODBC Driver 17 for SQL Server]Communication link failure (0) (SQLEndTran(SQL_ROLLBACK))')
WARNING:root:something raised an exception:
Traceback (most recent call last):
  File "/home/namor/Desktop/Vulnerability-Checker/db_handler.py", line 231, in exec_insert
    cur.execute(query, *params)
pyodbc.OperationalError: ('08S01', '[08S01] [Microsoft][ODBC Driver 17 for SQL Server]Communication link failure (0) (SQLExecDirectW)')

During handling of the above exception, another exception occurred:

Traceback (most recent call last):
  File "/home/namor/Desktop/Vulnerability-Checker/db_handler.py", line 234, in exec_insert
    cur.close()
pyodbc.OperationalError: ('08S01', '[08S01] [Microsoft][ODBC Driver 17 for SQL Server]Communication link failure (0) (SQLEndTran(SQL_ROLLBACK))')
WARNING:root:something raised an exception:
Traceback (most recent call last):
  File "/home/namor/Desktop/Vulnerability-Checker/db_handler.py", line 231, in exec_insert
    cur.execute(query, *params)
pyodbc.OperationalError: ('08S01', '[08S01] [Microsoft][ODBC Driver 17 for SQL Server]Communication link failure (0) (SQLExecDirectW)')

During handling of the above exception, another exception occurred:

Traceback (most recent call last):
  File "/home/namor/Desktop/Vulnerability-Checker/db_handler.py", line 234, in exec_insert
    cur.close()
pyodbc.OperationalError: ('08S01', '[08S01] [Microsoft][ODBC Driver 17 for SQL Server]Communication link failure (0) (SQLEndTran(SQL_ROLLBACK))')
WARNING:root:something raised an exception:
Traceback (most recent call last):
  File "/home/namor/Desktop/Vulnerability-Checker/db_handler.py", line 231, in exec_insert
    cur.execute(query, *params)
pyodbc.OperationalError: ('08S01', '[08S01] [Microsoft][ODBC Driver 17 for SQL Server]Communication link failure (0) (SQLExecDirectW)')

During handling of the above exception, another exception occurred:

Traceback (most recent call last):
  File "/home/namor/Desktop/Vulnerability-Checker/db_handler.py", line 234, in exec_insert
    cur.close()
pyodbc.OperationalError: ('08S01', '[08S01] [Microsoft][ODBC Driver 17 for SQL Server]Communication link failure (0) (SQLEndTran(SQL_ROLLBACK))')
WARNING:root:something raised an exception:
Traceback (most recent call last):
  File "/home/namor/Desktop/Vulnerability-Checker/db_handler.py", line 231, in exec_insert
    cur.execute(query, *params)
pyodbc.OperationalError: ('08S01', '[08S01] [Microsoft][ODBC Driver 17 for SQL Server]Communication link failure (0) (SQLExecDirectW)')

During handling of the above exception, another exception occurred:

Traceback (most recent call last):
  File "/home/namor/Desktop/Vulnerability-Checker/db_handler.py", line 234, in exec_insert
    cur.close()
pyodbc.OperationalError: ('08S01', '[08S01] [Microsoft][ODBC Driver 17 for SQL Server]Communication link failure (0) (SQLEndTran(SQL_ROLLBACK))')
WARNING:root:something raised an exception:
Traceback (most recent call last):
  File "/home/namor/Desktop/Vulnerability-Checker/db_handler.py", line 231, in exec_insert
    cur.execute(query, *params)
pyodbc.OperationalError: ('08S01', '[08S01] [Microsoft][ODBC Driver 17 for SQL Server]Communication link failure (0) (SQLExecDirectW)')

During handling of the above exception, another exception occurred:

Traceback (most recent call last):
  File "/home/namor/Desktop/Vulnerability-Checker/db_handler.py", line 234, in exec_insert
    cur.close()
pyodbc.OperationalError: ('08S01', '[08S01] [Microsoft][ODBC Driver 17 for SQL Server]Communication link failure (0) (SQLEndTran(SQL_ROLLBACK))')
WARNING:root:something raised an exception:
Traceback (most recent call last):
  File "/home/namor/Desktop/Vulnerability-Checker/db_handler.py", line 231, in exec_insert
    cur.execute(query, *params)
pyodbc.OperationalError: ('08S01', '[08S01] [Microsoft][ODBC Driver 17 for SQL Server]Communication link failure (0) (SQLExecDirectW)')

During handling of the above exception, another exception occurred:

Traceback (most recent call last):
  File "/home/namor/Desktop/Vulnerability-Checker/db_handler.py", line 234, in exec_insert
    cur.close()
pyodbc.OperationalError: ('08S01', '[08S01] [Microsoft][ODBC Driver 17 for SQL Server]Communication link failure (0) (SQLEndTran(SQL_ROLLBACK))')
WARNING:root:something raised an exception:
Traceback (most recent call last):
  File "/home/namor/Desktop/Vulnerability-Checker/db_handler.py", line 231, in exec_insert
    cur.execute(query, *params)
pyodbc.OperationalError: ('08S01', '[08S01] [Microsoft][ODBC Driver 17 for SQL Server]Communication link failure (0) (SQLExecDirectW)')

During handling of the above exception, another exception occurred:

Traceback (most recent call last):
  File "/home/namor/Desktop/Vulnerability-Checker/db_handler.py", line 234, in exec_insert
    cur.close()
pyodbc.OperationalError: ('08S01', '[08S01] [Microsoft][ODBC Driver 17 for SQL Server]Communication link failure (0) (SQLEndTran(SQL_ROLLBACK))')
WARNING:root:something raised an exception:
Traceback (most recent call last):
  File "/home/namor/Desktop/Vulnerability-Checker/db_handler.py", line 231, in exec_insert
    cur.execute(query, *params)
pyodbc.OperationalError: ('08S01', '[08S01] [Microsoft][ODBC Driver 17 for SQL Server]Communication link failure (0) (SQLExecDirectW)')

During handling of the above exception, another exception occurred:

Traceback (most recent call last):
  File "/home/namor/Desktop/Vulnerability-Checker/db_handler.py", line 234, in exec_insert
    cur.close()
pyodbc.OperationalError: ('08S01', '[08S01] [Microsoft][ODBC Driver 17 for SQL Server]Communication link failure (0) (SQLEndTran(SQL_ROLLBACK))')
WARNING:root:something raised an exception:
Traceback (most recent call last):
  File "/home/namor/Desktop/Vulnerability-Checker/db_handler.py", line 231, in exec_insert
    cur.execute(query, *params)
pyodbc.OperationalError: ('08S01', '[08S01] [Microsoft][ODBC Driver 17 for SQL Server]Communication link failure (0) (SQLExecDirectW)')

During handling of the above exception, another exception occurred:

Traceback (most recent call last):
  File "/home/namor/Desktop/Vulnerability-Checker/db_handler.py", line 234, in exec_insert
    cur.close()
pyodbc.OperationalError: ('08S01', '[08S01] [Microsoft][ODBC Driver 17 for SQL Server]Communication link failure (0) (SQLEndTran(SQL_ROLLBACK))')
WARNING:root:something raised an exception:
Traceback (most recent call last):
  File "/home/namor/Desktop/Vulnerability-Checker/db_handler.py", line 231, in exec_insert
    cur.execute(query, *params)
pyodbc.OperationalError: ('08S01', '[08S01] [Microsoft][ODBC Driver 17 for SQL Server]Communication link failure (0) (SQLExecDirectW)')

During handling of the above exception, another exception occurred:

Traceback (most recent call last):
  File "/home/namor/Desktop/Vulnerability-Checker/db_handler.py", line 234, in exec_insert
    cur.close()
pyodbc.OperationalError: ('08S01', '[08S01] [Microsoft][ODBC Driver 17 for SQL Server]Communication link failure (0) (SQLEndTran(SQL_ROLLBACK))')
WARNING:root:something raised an exception:
Traceback (most recent call last):
  File "/home/namor/Desktop/Vulnerability-Checker/db_handler.py", line 231, in exec_insert
    cur.execute(query, *params)
pyodbc.OperationalError: ('08S01', '[08S01] [Microsoft][ODBC Driver 17 for SQL Server]Communication link failure (0) (SQLExecDirectW)')

During handling of the above exception, another exception occurred:

Traceback (most recent call last):
  File "/home/namor/Desktop/Vulnerability-Checker/db_handler.py", line 234, in exec_insert
    cur.close()
pyodbc.OperationalError: ('08S01', '[08S01] [Microsoft][ODBC Driver 17 for SQL Server]Communication link failure (0) (SQLEndTran(SQL_ROLLBACK))')
WARNING:root:something raised an exception:
Traceback (most recent call last):
  File "/home/namor/Desktop/Vulnerability-Checker/db_handler.py", line 231, in exec_insert
    cur.execute(query, *params)
pyodbc.OperationalError: ('08S01', '[08S01] [Microsoft][ODBC Driver 17 for SQL Server]Communication link failure (0) (SQLExecDirectW)')

During handling of the above exception, another exception occurred:

Traceback (most recent call last):
  File "/home/namor/Desktop/Vulnerability-Checker/db_handler.py", line 234, in exec_insert
    cur.close()
pyodbc.OperationalError: ('08S01', '[08S01] [Microsoft][ODBC Driver 17 for SQL Server]Communication link failure (0) (SQLEndTran(SQL_ROLLBACK))')
WARNING:root:something raised an exception:
Traceback (most recent call last):
  File "/home/namor/Desktop/Vulnerability-Checker/db_handler.py", line 218, in exec_query
    cur.execute(query)
pyodbc.OperationalError: ('08S01', '[08S01] [Microsoft][ODBC Driver 17 for SQL Server]Communication link failure (0) (SQLExecDirectW)')

During handling of the above exception, another exception occurred:

Traceback (most recent call last):
  File "/home/namor/Desktop/Vulnerability-Checker/db_handler.py", line 221, in exec_query
    return rows
pyodbc.OperationalError: ('08S01', '[08S01] [Microsoft][ODBC Driver 17 for SQL Server]Communication link failure (0) (SQLEndTran(SQL_ROLLBACK))')
WARNING:root:something raised an exception:
Traceback (most recent call last):
  File "/home/namor/Desktop/Vulnerability-Checker/db_handler.py", line 231, in exec_insert
    cur.execute(query, *params)
pyodbc.ProgrammingError: ('42000', '[42000] [Microsoft][ODBC Driver 17 for SQL Server][SQL Server]Conversion failed when converting from a character string to uniqueidentifier. (8169) (SQLExecDirectW)')
WARNING:root:something raised an exception:
Traceback (most recent call last):
  File "/home/namor/Desktop/Vulnerability-Checker/db_handler.py", line 231, in exec_insert
    cur.execute(query, *params)
pyodbc.ProgrammingError: ('42000', '[42000] [Microsoft][ODBC Driver 17 for SQL Server][SQL Server]Conversion failed when converting from a character string to uniqueidentifier. (8169) (SQLExecDirectW)')
WARNING:root:something raised an exception:
Traceback (most recent call last):
  File "/home/namor/Desktop/Vulnerability-Checker/db_handler.py", line 231, in exec_insert
    cur.execute(query, *params)
pyodbc.ProgrammingError: ('42000', '[42000] [Microsoft][ODBC Driver 17 for SQL Server][SQL Server]Conversion failed when converting from a character string to uniqueidentifier. (8169) (SQLExecDirectW)')
WARNING:root:something raised an exception:
Traceback (most recent call last):
  File "/home/namor/Desktop/Vulnerability-Checker/db_handler.py", line 231, in exec_insert
    cur.execute(query, *params)
pyodbc.ProgrammingError: ('42000', '[42000] [Microsoft][ODBC Driver 17 for SQL Server][SQL Server]Conversion failed when converting from a character string to uniqueidentifier. (8169) (SQLExecDirectW)')
WARNING:root:something raised an exception:
Traceback (most recent call last):
  File "/usr/lib64/python3.6/encodings/utf_16_le.py", line 15, in decode
    def decode(input, errors='strict'):
KeyboardInterrupt

The above exception was the direct cause of the following exception:

KeyboardInterrupt: decoding with 'utf-16le' codec failed (KeyboardInterrupt: )

The above exception was the direct cause of the following exception:

Traceback (most recent call last):
  File "/home/namor/Desktop/Vulnerability-Checker/db_handler.py", line 231, in exec_insert
    cur.execute(query, *params)
SystemError: <class 'pyodbc.Error'> returned a result with an error set

During handling of the above exception, another exception occurred:

Traceback (most recent call last):
  File "/home/namor/Desktop/Vulnerability-Checker/db_handler.py", line 234, in exec_insert
    cur.close()
pyodbc.OperationalError: ('08S01', '[08S01] [Microsoft][ODBC Driver 17 for SQL Server]Communication link failure (-2147467259) (SQLEndTran(SQL_ROLLBACK))')
WARNING:root:something raised an exception:
Traceback (most recent call last):
  File "/home/namor/Desktop/Vulnerability-Checker/db_handler.py", line 231, in exec_insert
    cur.execute(query, *params)
pyodbc.OperationalError: ('08S01', '[08S01] [Microsoft][ODBC Driver 17 for SQL Server]Communication link failure (0) (SQLExecDirectW)')

During handling of the above exception, another exception occurred:

Traceback (most recent call last):
  File "/home/namor/Desktop/Vulnerability-Checker/db_handler.py", line 234, in exec_insert
    cur.close()
pyodbc.OperationalError: ('08S01', '[08S01] [Microsoft][ODBC Driver 17 for SQL Server]Communication link failure (0) (SQLEndTran(SQL_ROLLBACK))')
WARNING:root:something raised an exception:
Traceback (most recent call last):
  File "/home/namor/Desktop/Vulnerability-Checker/db_handler.py", line 231, in exec_insert
    cur.execute(query, *params)
pyodbc.OperationalError: ('08S01', '[08S01] [Microsoft][ODBC Driver 17 for SQL Server]Communication link failure (0) (SQLExecDirectW)')

During handling of the above exception, another exception occurred:

Traceback (most recent call last):
  File "/home/namor/Desktop/Vulnerability-Checker/db_handler.py", line 234, in exec_insert
    cur.close()
pyodbc.OperationalError: ('08S01', '[08S01] [Microsoft][ODBC Driver 17 for SQL Server]Communication link failure (0) (SQLEndTran(SQL_ROLLBACK))')
WARNING:root:something raised an exception:
Traceback (most recent call last):
  File "/home/namor/Desktop/Vulnerability-Checker/db_handler.py", line 218, in exec_query
    cur.execute(query)
pyodbc.OperationalError: ('08S01', '[08S01] [Microsoft][ODBC Driver 17 for SQL Server]Communication link failure (0) (SQLExecDirectW)')

During handling of the above exception, another exception occurred:

Traceback (most recent call last):
  File "/home/namor/Desktop/Vulnerability-Checker/db_handler.py", line 221, in exec_query
    return rows
pyodbc.OperationalError: ('08S01', '[08S01] [Microsoft][ODBC Driver 17 for SQL Server]Communication link failure (0) (SQLEndTran(SQL_ROLLBACK))')
WARNING:root:something raised an exception:
Traceback (most recent call last):
  File "/usr/lib64/python3.6/encodings/utf_16_le.py", line 15, in decode
    def decode(input, errors='strict'):
KeyboardInterrupt

The above exception was the direct cause of the following exception:

KeyboardInterrupt: decoding with 'utf-16le' codec failed (KeyboardInterrupt: )

The above exception was the direct cause of the following exception:

Traceback (most recent call last):
  File "/home/namor/Desktop/Vulnerability-Checker/db_handler.py", line 231, in exec_insert
    cur.execute(query, *params)
SystemError: <class 'pyodbc.Error'> returned a result with an error set

During handling of the above exception, another exception occurred:

Traceback (most recent call last):
  File "/home/namor/Desktop/Vulnerability-Checker/db_handler.py", line 234, in exec_insert
    cur.close()
pyodbc.OperationalError: ('08S01', '[08S01] [Microsoft][ODBC Driver 17 for SQL Server]Communication link failure (-2147467259) (SQLEndTran(SQL_ROLLBACK))')
WARNING:root:something raised an exception:
Traceback (most recent call last):
  File "/home/namor/Desktop/Vulnerability-Checker/db_handler.py", line 218, in exec_query
    cur.execute(query)
pyodbc.OperationalError: ('08S01', '[08S01] [Microsoft][ODBC Driver 17 for SQL Server]Communication link failure (0) (SQLExecDirectW)')

During handling of the above exception, another exception occurred:

Traceback (most recent call last):
  File "/home/namor/Desktop/Vulnerability-Checker/db_handler.py", line 221, in exec_query
    return rows
pyodbc.OperationalError: ('08S01', '[08S01] [Microsoft][ODBC Driver 17 for SQL Server]Communication link failure (0) (SQLEndTran(SQL_ROLLBACK))')
WARNING:root:something raised an exception:
Traceback (most recent call last):
  File "/usr/lib/python3.6/encodings/utf_16_le.py", line 15, in decode
    def decode(input, errors='strict'):
KeyboardInterrupt

The above exception was the direct cause of the following exception:

KeyboardInterrupt: decoding with 'utf-16le' codec failed (KeyboardInterrupt: )

The above exception was the direct cause of the following exception:

Traceback (most recent call last):
  File "/home/avi/Vulnerability-Checker/db_handler.py", line 231, in exec_insert
    cur.execute(query, *params)
SystemError: <class 'pyodbc.Error'> returned a result with an error set

During handling of the above exception, another exception occurred:

Traceback (most recent call last):
  File "/home/avi/Vulnerability-Checker/db_handler.py", line 234, in exec_insert
    cur.close()
pyodbc.OperationalError: ('08S01', '[08S01] [Microsoft][ODBC Driver 17 for SQL Server]Communication link failure (-2147467259) (SQLEndTran(SQL_ROLLBACK))')
WARNING:root:something raised an exception:
Traceback (most recent call last):
  File "/home/avi/Vulnerability-Checker/db_handler.py", line 218, in exec_query
    cur.execute(query)
pyodbc.OperationalError: ('08S01', '[08S01] [Microsoft][ODBC Driver 17 for SQL Server]Communication link failure (0) (SQLExecDirectW)')

During handling of the above exception, another exception occurred:

Traceback (most recent call last):
  File "/home/avi/Vulnerability-Checker/db_handler.py", line 221, in exec_query
    return rows
pyodbc.OperationalError: ('08S01', '[08S01] [Microsoft][ODBC Driver 17 for SQL Server]Communication link failure (0) (SQLEndTran(SQL_ROLLBACK))')
